2018-06-26 12:38:16,406 INFO: Microblog startup [in /Users/ripzy/Projects/microblog/app/__init__.py:47]
2018-06-26 12:38:55,640 ERROR: Exception on /edit_profile [POST] [in /Users/ripzy/Projects/microblog/venv/lib/python3.6/site-packages/flask/app.py:1761]
Traceback (most recent call last):
  File "/Users/ripzy/Projects/microblog/venv/lib/python3.6/site-packages/sqlalchemy/engine/base.py", line 1193, in _execute_context
    context)
  File "/Users/ripzy/Projects/microblog/venv/lib/python3.6/site-packages/sqlalchemy/engine/default.py", line 508, in do_execute
    cursor.execute(statement, parameters)
sqlite3.IntegrityError: UNIQUE constraint failed: user.username

The above exception was the direct cause of the following exception:

Traceback (most recent call last):
  File "/Users/ripzy/Projects/microblog/venv/lib/python3.6/site-packages/flask/app.py", line 2292, in wsgi_app
    response = self.full_dispatch_request()
  File "/Users/ripzy/Projects/microblog/venv/lib/python3.6/site-packages/flask/app.py", line 1815, in full_dispatch_request
    rv = self.handle_user_exception(e)
  File "/Users/ripzy/Projects/microblog/venv/lib/python3.6/site-packages/flask/app.py", line 1718, in handle_user_exception
    reraise(exc_type, exc_value, tb)
  File "/Users/ripzy/Projects/microblog/venv/lib/python3.6/site-packages/flask/_compat.py", line 35, in reraise
    raise value
  File "/Users/ripzy/Projects/microblog/venv/lib/python3.6/site-packages/flask/app.py", line 1813, in full_dispatch_request
    rv = self.dispatch_request()
  File "/Users/ripzy/Projects/microblog/venv/lib/python3.6/site-packages/flask/app.py", line 1799, in dispatch_request
    return self.view_functions[rule.endpoint](**req.view_args)
  File "/Users/ripzy/Projects/microblog/venv/lib/python3.6/site-packages/flask_login/utils.py", line 261, in decorated_view
    return func(*args, **kwargs)
  File "/Users/ripzy/Projects/microblog/app/routes.py", line 88, in edit_profile
    db.session.commit()
  File "/Users/ripzy/Projects/microblog/venv/lib/python3.6/site-packages/sqlalchemy/orm/scoping.py", line 153, in do
    return getattr(self.registry(), name)(*args, **kwargs)
  File "/Users/ripzy/Projects/microblog/venv/lib/python3.6/site-packages/sqlalchemy/orm/session.py", line 943, in commit
    self.transaction.commit()
  File "/Users/ripzy/Projects/microblog/venv/lib/python3.6/site-packages/sqlalchemy/orm/session.py", line 467, in commit
    self._prepare_impl()
  File "/Users/ripzy/Projects/microblog/venv/lib/python3.6/site-packages/sqlalchemy/orm/session.py", line 447, in _prepare_impl
    self.session.flush()
  File "/Users/ripzy/Projects/microblog/venv/lib/python3.6/site-packages/sqlalchemy/orm/session.py", line 2254, in flush
    self._flush(objects)
  File "/Users/ripzy/Projects/microblog/venv/lib/python3.6/site-packages/sqlalchemy/orm/session.py", line 2380, in _flush
    transaction.rollback(_capture_exception=True)
  File "/Users/ripzy/Projects/microblog/venv/lib/python3.6/site-packages/sqlalchemy/util/langhelpers.py", line 66, in __exit__
    compat.reraise(exc_type, exc_value, exc_tb)
  File "/Users/ripzy/Projects/microblog/venv/lib/python3.6/site-packages/sqlalchemy/util/compat.py", line 187, in reraise
    raise value
  File "/Users/ripzy/Projects/microblog/venv/lib/python3.6/site-packages/sqlalchemy/orm/session.py", line 2344, in _flush
    flush_context.execute()
  File "/Users/ripzy/Projects/microblog/venv/lib/python3.6/site-packages/sqlalchemy/orm/unitofwork.py", line 391, in execute
    rec.execute(self)
  File "/Users/ripzy/Projects/microblog/venv/lib/python3.6/site-packages/sqlalchemy/orm/unitofwork.py", line 556, in execute
    uow
  File "/Users/ripzy/Projects/microblog/venv/lib/python3.6/site-packages/sqlalchemy/orm/persistence.py", line 177, in save_obj
    mapper, table, update)
  File "/Users/ripzy/Projects/microblog/venv/lib/python3.6/site-packages/sqlalchemy/orm/persistence.py", line 768, in _emit_update_statements
    execute(statement, multiparams)
  File "/Users/ripzy/Projects/microblog/venv/lib/python3.6/site-packages/sqlalchemy/engine/base.py", line 948, in execute
    return meth(self, multiparams, params)
  File "/Users/ripzy/Projects/microblog/venv/lib/python3.6/site-packages/sqlalchemy/sql/elements.py", line 269, in _execute_on_connection
    return connection._execute_clauseelement(self, multiparams, params)
  File "/Users/ripzy/Projects/microblog/venv/lib/python3.6/site-packages/sqlalchemy/engine/base.py", line 1060, in _execute_clauseelement
    compiled_sql, distilled_params
  File "/Users/ripzy/Projects/microblog/venv/lib/python3.6/site-packages/sqlalchemy/engine/base.py", line 1200, in _execute_context
    context)
  File "/Users/ripzy/Projects/microblog/venv/lib/python3.6/site-packages/sqlalchemy/engine/base.py", line 1413, in _handle_dbapi_exception
    exc_info
  File "/Users/ripzy/Projects/microblog/venv/lib/python3.6/site-packages/sqlalchemy/util/compat.py", line 203, in raise_from_cause
    reraise(type(exception), exception, tb=exc_tb, cause=cause)
  File "/Users/ripzy/Projects/microblog/venv/lib/python3.6/site-packages/sqlalchemy/util/compat.py", line 186, in reraise
    raise value.with_traceback(tb)
  File "/Users/ripzy/Projects/microblog/venv/lib/python3.6/site-packages/sqlalchemy/engine/base.py", line 1193, in _execute_context
    context)
  File "/Users/ripzy/Projects/microblog/venv/lib/python3.6/site-packages/sqlalchemy/engine/default.py", line 508, in do_execute
    cursor.execute(statement, parameters)
sqlalchemy.exc.IntegrityError: (sqlite3.IntegrityError) UNIQUE constraint failed: user.username [SQL: 'UPDATE user SET username=?, about_me=? WHERE user.id = ?'] [parameters: ('jan', '"Hello World! Yehey!" - Unknown', 1)] (Background on this error at: http://sqlalche.me/e/gkpj)
2018-06-26 12:47:31,093 INFO: Microblog startup [in /Users/ripzy/Projects/microblog/app/__init__.py:47]
2018-06-26 12:48:40,123 INFO: Microblog startup [in /Users/ripzy/Projects/microblog/app/__init__.py:47]
2018-06-26 12:53:39,188 INFO: Microblog startup [in /Users/ripzy/Projects/microblog/app/__init__.py:47]
2018-06-26 12:55:11,497 INFO: Microblog startup [in /Users/ripzy/Projects/microblog/app/__init__.py:47]
2018-06-26 12:57:05,131 INFO: Microblog startup [in /Users/ripzy/Projects/microblog/app/__init__.py:47]
2018-06-26 12:57:34,732 INFO: Microblog startup [in /Users/ripzy/Projects/microblog/app/__init__.py:47]
2018-06-26 12:58:04,417 ERROR: Exception on /edit_profile [POST] [in /Users/ripzy/Projects/microblog/venv/lib/python3.6/site-packages/flask/app.py:1761]
Traceback (most recent call last):
  File "/Users/ripzy/Projects/microblog/venv/lib/python3.6/site-packages/flask/app.py", line 2292, in wsgi_app
    response = self.full_dispatch_request()
  File "/Users/ripzy/Projects/microblog/venv/lib/python3.6/site-packages/flask/app.py", line 1816, in full_dispatch_request
    return self.finalize_request(rv)
  File "/Users/ripzy/Projects/microblog/venv/lib/python3.6/site-packages/flask/app.py", line 1831, in finalize_request
    response = self.make_response(rv)
  File "/Users/ripzy/Projects/microblog/venv/lib/python3.6/site-packages/flask/app.py", line 1957, in make_response
    'The view function did not return a valid response. The'
TypeError: The view function did not return a valid response. The function either returned None or ended without a return statement.
2018-06-26 12:58:14,340 ERROR: Exception on /edit_profile [POST] [in /Users/ripzy/Projects/microblog/venv/lib/python3.6/site-packages/flask/app.py:1761]
Traceback (most recent call last):
  File "/Users/ripzy/Projects/microblog/venv/lib/python3.6/site-packages/flask/app.py", line 2292, in wsgi_app
    response = self.full_dispatch_request()
  File "/Users/ripzy/Projects/microblog/venv/lib/python3.6/site-packages/flask/app.py", line 1816, in full_dispatch_request
    return self.finalize_request(rv)
  File "/Users/ripzy/Projects/microblog/venv/lib/python3.6/site-packages/flask/app.py", line 1831, in finalize_request
    response = self.make_response(rv)
  File "/Users/ripzy/Projects/microblog/venv/lib/python3.6/site-packages/flask/app.py", line 1957, in make_response
    'The view function did not return a valid response. The'
TypeError: The view function did not return a valid response. The function either returned None or ended without a return statement.
2018-06-26 12:58:23,512 INFO: Microblog startup [in /Users/ripzy/Projects/microblog/app/__init__.py:47]
2018-06-26 12:58:33,580 ERROR: Exception on /edit_profile [POST] [in /Users/ripzy/Projects/microblog/venv/lib/python3.6/site-packages/flask/app.py:1761]
Traceback (most recent call last):
  File "/Users/ripzy/Projects/microblog/venv/lib/python3.6/site-packages/flask/app.py", line 2292, in wsgi_app
    response = self.full_dispatch_request()
  File "/Users/ripzy/Projects/microblog/venv/lib/python3.6/site-packages/flask/app.py", line 1816, in full_dispatch_request
    return self.finalize_request(rv)
  File "/Users/ripzy/Projects/microblog/venv/lib/python3.6/site-packages/flask/app.py", line 1831, in finalize_request
    response = self.make_response(rv)
  File "/Users/ripzy/Projects/microblog/venv/lib/python3.6/site-packages/flask/app.py", line 1957, in make_response
    'The view function did not return a valid response. The'
TypeError: The view function did not return a valid response. The function either returned None or ended without a return statement.
2018-06-26 12:58:52,266 INFO: Microblog startup [in /Users/ripzy/Projects/microblog/app/__init__.py:47]
